Workbook
Name _1Schubmaststap: '[1]master data equipment'!#REF!
Name _2Schubmaststap: '[2]master data equipment'!#REF!
Name _2Schubmaststap: '[1]master data equipment'!#REF!
Name _2Schubmaststap: '[1]master data equipment'!#REF!
Name _DAT10: '[3]AfA + Zinsen'!#REF!
Name _DAT11: '[3]AfA + Zinsen'!#REF!
Name _DAT12: '[3]AfA + Zinsen'!#REF!
Name _DAT14: '[3]AfA + Zinsen'!#REF!
Name _DAT16: '[3]AfA + Zinsen'!#REF!
Name _DAT17: '[3]AfA + Zinsen'!#REF!
Name _DAT18: '[3]AfA + Zinsen'!#REF!
Name _DAT19: '[3]AfA + Zinsen'!#REF!
Name _DAT20: '[3]AfA + Zinsen'!#REF!
Name _DAT21: '[3]AfA + Zinsen'!#REF!
Name _DAT7: '[3]AfA + Zinsen'!#REF!
Name _DAT8: '[3]AfA + Zinsen'!#REF!
Name _DAT9: '[3]AfA + Zinsen'!#REF!
Name _dlr: [4]Allg!$G$3
Name _dlr: [5]Allg!$G$3
Name _eur1: #REF!
Name _ts1: #REF!
Name A_SEC_VPL_TEIL_STAT_020806: #REF!
Name Abladebereiche: #REF!
Name Ablage: #REF!
Name Add_Zeile: #REF!
Name Additional_Packaging: '[8]basic data packaging'!$B$8:$B$116
Name AL35M7_01: [9]Thailand!#REF!
Name AL35M7_02: [9]Thailand!#REF!
Name AL35M7_03: [9]Thailand!#REF!
Name AL35M7_04: [9]Thailand!#REF!
Name AL35M7_05: [9]Thailand!#REF!
Name AL35M7_06: [9]Thailand!#REF!
Name AL35M7_07: [9]Thailand!#REF!
Name AL35M7_08: [9]Thailand!#REF!
Name AL35M7_09: [9]Thailand!#REF!
Name AL35M7_10: [9]Thailand!#REF!
Name AL35M7_11: [9]Thailand!#REF!
Name AL35M7_12: [9]Thailand!#REF!
Name AL35M7_Gesamt: [9]Thailand!#REF!
Name Anlauf6: [10]Kalkulationsbasis!$S$196
Name Anlauf6: [11]Kalkulationsbasis!$S$196
Name Arbeitsbereich: #REF!
Name Arbeitstage_Februar: [12]Eing_BASIS!$D$8
Name Arbeitstage_Februar: [13]Eing_BASIS!$D$8
Name Arbeitstage_Januar: [12]Eing_BASIS!$C$8
Name Arbeitstage_Januar: [13]Eing_BASIS!$C$8
Name Arbeitstage_März: [12]Eing_BASIS!$E$8
Name Arbeitstage_März: [13]Eing_BASIS!$E$8
Name AT_Jahr: [14]Parameter!$B$4
Name ATL_Basis_SAM_Fertig: #REF!
Name Ausführender: #REF!
Name Ausgangsdaten: [15]Ergebnis!$E$3:$AK$6
Name Ausgangsdaten: [16]Ergebnis!$E$3:$AK$6
Name Ausgangsregionen: [15]Ergebnis!$E$3:$E$6
Name Ausgangsregionen: [16]Ergebnis!$E$3:$E$6
Name Ausschuß: #REF!
Name Ausschuß: #REF!
Name Basic: #REF!
Name Basisjahr: #REF!
Name Bearbeitungsstand: [17]Basic_Units!$S$3:$S$6

Sheet Cover Sheet
A6: Exhibit 03
A8: Volume Information
A10: Logistics Services Agreement
A12: Regional Distribution Centre Ningbo
A14: P.R. of China
A17: Annotation
A18: The volume information which is mentioned in this Exhibit of that contract has been compiled by BBA to the best of BBA’s knowledge. Nevertheless it should be understood just as planning basis for the Contractor. The given volumes are indicative and could change. Therefore they cannot be guaranteed.

Sheet 问题清单
A1: # | B1: Source | C1: Category | D1: Question | E1: Critial | F1: On-site checking | G1: Answer
A2: 1 | B2: Appendix 23_Shanghai warehouse layout | C2: Storage | D2: 提供仓库的长度/宽度，标注每个storage area的长宽数据，最好可以提供CAD文件 | E2: Y
A3: 2 | B3: Appendix 23_Shanghai warehouse layout | C3: Storage | D3: 标书提到了对现有布局及货架的优化，但是目前我们没有在表述中看到目前的库存数据、每种货架类型的货位情况等； | E3: Y | F3: Y | G3: the optimizations in regards to the cost reduction, space utilization, efficiency increasing, etc. are always more than welcome to us. please take the opptunities of warehouse visit to see our operations and raised your ideas in proposal
A4: 3 | B4: Appendix 23_Shanghai warehouse layout | C4: Storage | D4: 现场了解相关情况，以及目前各类货架的利用率情况，痛点和瓶颈 | E4: Y | F4: Y | G4: 现场货架利用率目测大于85%，痛点和瓶颈未回复
A5: 4 | B5: Appendix 23_Shanghai warehouse layout | C5: Storage | D5: 在layout图看到Cross Docking Area 94平方米，请问cross docking有多少量？ | G5: 0.05
A6: 5 | B6: Appendix 3_Warehouse operation data | D6: 我们的操作能力需要在日平均的基础上考虑多少高峰加成？ | G6: 未明确回复，满足RFP文档中的货量需求即可
A7: 6 | B7: Appendix 3_Warehouse operation data Appendix 2_Inbound volume | C7: Inbound | D7: Appendix 2_Inbound volume 中Order Type分为Stock和Express，但是Appendix 3_Warehouse operation data中"Inbound Lines Express per working day (average)"是用Inbound Lines per year总量除以293天，是否可以分别提供Stock和Express的量 | E7: Y | H7: ~50% goods in container has pallet, and ~50% carton are mix SKU carton
A8: 7 | B8: Appendix 3_Warehouse operation data | C8: Inbound | D8: 每周到货的kolli数量，或Avergae # of orderline/kolli | E8: Y | G8: just for reference Large/Bulky 58% M2 14% M1 6% Small 14% ust for reference small 9 pcs/line M1 36 pcs/line M2 40 pcs/line Large 4pcs/line
A9: 8 | B9: Appendix 3_Warehouse operation data | C9: Inbound | D9: 是否只有当carton 外包装破损的什么情况下需要full inspection | G9: full inspection rate 3%~8%
A10: 9 | B10: Appendix 3_Warehouse operation data | C10: Inbound | D10: 到货orderline存放到不同区域的比列（Shelves area/Medium Parts Racking area/Large Parts Racking Area/Floor Storage area） | E10: Y
A11: 10 | B11: Appendix 3_Warehouse operation data | C11: Outbound | D11: "Outbound Lines (Dealer orders)"是否包含VOR? VOR的比列是多少？ | E11: Y
A12: 11 | B12: Appendix 9 Warehouse Quotation table | C12: Outbound | D12: Outbound # of packing cartons 是否可以参照3_packaging cost中第1-12行Avg. consumption/month作为包装出货量计算 | E12: Y
A13: 12 | B13: Appendix 9 Warehouse Quotation table | C13: Outbound | D13: Outbound # of packing cartons 是否可以参照3_packaging cost中第1-3行Small-Avg. consumption/month作为VOR包装出货量计算 | E13: Y
A14: 13 | B14: Appendix 3_Warehouse operation data | C14: Outbound | D14: 分别从不同区域picking的orderline比列（Shelves area/Medium Parts Racking area/Large Parts Racking Area/Floor Storage area） | E14: Y | G14: Large/Bulky 30% M2 27% M1 12% Small 29%
A15: 14 | B15: 00_Tender Document Porsche China Shanghai Lingang warehouse | D15: 目前的CCTV等监控设备是否会留用？ | F15: Y | G15: CCTV system needs to be replaced Tempreture&humidity sensor need to be setup furnitures&office renovation, security system belong to current 3PL
A16: 15 | B16: 00_Tender Document Porsche China Shanghai Lingang warehouse | D16: 关于地坪，现场需评估和讨论一下如何包括地坪成本 | F16: Y | G16: No need for newly floor coating renovation, but supplier will be responsible for the repair in case of damage following the requirements in appendix
A17: 16 | B17: 00_Tender Document Porsche China Shanghai Lingang warehouse | D17: 总体了解一下关于可能搬新仓的问题，因为设计到货架的重新布局安装，旧货架拆除，场地恢复，库位标签更改地坪，搬仓费用，盘点费用等等； 这部分，除了新货架按报价表，其他部分是否到时另行报价 | F17: Y | G17: 不考虑搬仓
A18: 17 | B18: 00_Tender Document Porsche China Shanghai Lingang warehouse | D18: 整体关于目前的操作流程有哪些痛点和瓶颈，需要在以后的操作中予以解决 | F18: Y
A19: 18 | B19: 00_Tender Document Porsche China Shanghai Lingang warehouse | D19: Appendix 8 中提到了AGV和数字孪生，需要现场了解一下具体的内容。包括但不限于， a) 目前AGV的使用场景，具体到步骤；具体台数及配套设施和系统情况 b) 新合同期内AGV以后会留用在仓库么？ | E19: Y | F19: Y | G19: 1.仓库无AGV及任何自动化设备。如果供应商投入AGV，网络，服务器等需要供应商单独配置，保时捷不兼容。 2.保时捷的PDMS平台有孪生系统，会有拣货，库存，破损登记，工作量等数据显示，效率没有体现，也不是实时显示。仓库操作EWMS系统，没有与孪生系统对接（不支持对接）。
A20: 19 | B20: 00_Tender Document Porsche China Shanghai Lingang warehouse | D20: 需要澄清一下水电是否需要包括在报价中？ | E20: Y | G20: utilites cost is covered by PCN
A21: 20 | B21: 00_Tender Document Porsche China Shanghai Lingang warehouse | D21: 此外按理解例如虫控、垃圾清运等费用都属于运营费用，需要包括在报价中，请确认 | E21: Y
A22: 21 | B22: Appendix 5 _ Rack system Requirements | D22: 2.2.1 Large parts 第一到第三层是否为picking location? | E22: Y | F22: Y | G22: 没有拣货位和补货位的设置，一二层为快流件 | H22: 不补货？
A23: 22 | B23: Appendix 5 _ Rack system Requirements | D23: 2.2.2 Medium parts II 第一到第三层是否为picking location? | E23: Y | F23: Y | G23: 没有拣货位和补货位的设置，一二层为快流件
A24: 23 | B24: Appendix 4_Warehouse scope of service | D24: 2.3.8 Matrix of Responsibilities IT- Equipment – PC, label printer and laser printer Office decoration Office furniture & equipment, phone, internet access Cabling in warehouse and office areas Security and Alarm system 因为是现有仓库，以上这些是不是已经涵盖，还是需要重新装修配置？ | E24: Y | G24: security system，SP should put the quotation in quotation sheet “1.3 Start-up cost” office furniture needs to be included
A25: 24 | B25: Appendix 4_Warehouse scope of service | D25: 2.3.8 Matrix of Responsibilities Insurance是否需要包含inventory财产险，需提供inventory value
A26: 25 | B26: Appendix 9 Warehouse Quotation table | C26: DG warehouse | D26: DG rental根据面积大小报价，请问是否可以接受share DG warehouse，还是必须dedicated warehouse | E26: Y | G26: 可以
C27: DG warehouse | D27: Inbound DG processing/Outbound DG processing是否包含C5仓库的操作以及external DG warehouse操作？ | E27: Y | G27: 不包含C5
D29: This is our understanding for inbound process, please clarify if correct or not: 100% unloading by full pallet>>outer box visual check and count at carton level>>all inbound cartons are mix sku carton, need to open carton and check sku/quantity/quality/shelf life by unit level>>sorting small unit by sku and put into sorted tote or new empty pallet>>putaway onto shelf or rack | E29: goods in container are mixed, not in pallatization, ~50% goods in container has pallet, and ~50% carton are mix SKU carton
D30: How many DG inbound pieces per inbound orderline? | E30: ~1.7
D31: How many DG inbound orderline per year? Does following inbound orderlines already include DG? | E31: DG is included. rate is around 8%
D32: Average how many lines per inbound HU? | E32: 2.4
D33: How many order lines per outbound pack on average? | E33: 5
D34: How many DG outbound orderline per year per Y2026 forecast? | E34: ~14360
D35: How many DG outbound pieces in Y2026 forecast? | E35: ~27000
D36: What is the proportion of DG Warehouse in the provided order lines? 请提供货量中DG仓库的订单行数、及每个订单行的平均件数等数据 | E36: ~2%, 1.69
D37: We noted that Porsche’s contract does not allow any amendments and prohibits the inclusion of a liability cap.Could Porsche kindly confirm whether it would be open to negotiating the retention of a liability-cap clause? | E37: 1.Clause 16.2 Loss or Damage of PCN Goods In case you want to set a liability cap under this term, please pay attention to below statements. PCN’s average inventory value is approximately RMB 400 million. In addition to the obligations set forth in the Agreement, the Service Provider (SP) shall maintain a minimum liability cap sufficient to cover the full value of PCN’s inventory at risk, such that the sum of: (a) the SP’s insurance coverage limit for loss or damage to PCN Goods, and (b) the SP’s direct financial liability (i.e., the liability cap beyond insurance) shall in total be no less than RMB 400 million (or its equivalent in Euro). This liability cap in respect of loss or damage of PCN Goods aims to ensures that PCN is fully compensated for any loss or damage resulting from the SP’s acts, omissions, negligence, improper handling, operational faults, or breach of contract — including any amounts not covered, partially covered, or rejected by insurance. The SP shall provide evidence of its current insurance coverage and confirm its ability to meet the required liability cap as part of its bid submission. Should the SP’s existing insurance be insufficient, it must procure additional coverage or demonstrate equivalent financial capacity to meet the total liability requirement. The cost of any such measures must be fully reflected in the SP’s final pricing proposal. PCN reserves the right to review and verify the SP’s insurance coverage and financial liability capacity at any time during the contract term. Any adjustment to the liability cap for loss or damage of PCN Goods due to changes in inventory value shall be mutually agreed in writing by both parties, and may result in a corresponding, mutually agreed adjustment to service fees. 2. Clause 16.5 Limitation of Liability PCN does not accept any changes or negotiations
D38: How many security guards and cleaner HC in current normal warehouse? | E38: 4+1
D39: “Inventory (Counting lines per year)” include cycle count and stock take? | E39: no, annal stock take volume is excluded
D40: Please provide the qty of storage locations corresponding to different types of storage racks/shelves in the current warehouse. 请提供现有仓库不同货位类型货位的货位数量，以便计算交接盘点的资源数量 | E40: Shelves 22863 Medium 8505 Large 6979 Bulky 387
D41: pls provide the % of inbound and outbound order lines for warehouses C1, C2, and C5? C1 和C2,C5 仓库入库和出库订单行比例分别是多少? | E41: C1+C2 2% C5 2%
...

Sheet Prod check
A1: Cross checking
A2: 1. Putaway productivity adjust to 17 line/hour
A3: 2. Picking productivity adjust to 27 line/hour
A4: 3. Packing productivity adjust to 39 line/hour
A5: 4. indirect labour - 可考虑减少1个Supervisor的配置
B7: Productivity Reference | F7: Porsche Productivity
A8: Main Process | B8: Cal. FTE (9.2 hours/WD) | C8: Workload% | D8: Daily line/2026 | E8: Productivity (line/hour) | F8: Cal. FTE (6.8 hours/WD) BEFORE | G8: Cal. FTE (6.8 hours/WD) AFTER | H8: Workload% | I8: Daily line/2026 | J8: Productivity (line/hour) BEFORE | K8: Productivity (line/hour) AFTER | L8: Productivity Porche vs. Reference | M8: Cal. Workload Hours (impact by space) | N8: Cal. Productivity (impact by space)
A9: Receiving, Sorting & Labeling | B9: 7 | C9: =B9/$B$15 -> 0.074468085 | D9: 1141 | E9: 17.7 | G9: =SUM(Process!P2:P29) -> 5.5178831 | H9: =G9/$G$15 -> 0.15691622 | I9: =Volume!B9/Parameter!$P$4 -> 750.54266 | K9: =I9/G9/Parameter!$P$6/Parameter!$P$7 -> 20.002947 | L9: =K9/E9 -> 1.13011
A10: Put away | B10: 11 | C10: =B10/$B$15 -> 0.11702128 | E10: 11.3 | F10: 5.5971972 | G10: =SUM(Process!P30:P72) -> 6.2944072 | H10: =G10/$G$15 -> 0.17899883 | J10: 19.719498 | K10: =I9/G10/Parameter!$P$6/Parameter!$P$7 -> 17.535237 | L10: =K10/E10 -> 1.5517909 | M10: =B10*9.2*($B$21*$B$20+(1-$B$21)) -> 70.84 | N10: =D9/M10 -> 16.106719
A11: Sub. Inbound | B11: =SUM(B9:B10) -> 18 | C11: =SUM(C9:C10) -> 0.19148936 | D11: / | E11: 6.9 | G11: =SUM(G9:G10) -> 11.81229 | H11: =SUM(H9:H10) -> 0.33591505 | I11: / | K11: =I9/G11/Parameter!$P$6/Parameter!$P$7 -> 9.3439899 | L11: =K11/E11 -> 1.3542014
A12: Picking | B12: 47 | C12: =B12/$B$15 -> 0.5 | D12: 8271 | E12: 19.1 | F12: 9.835593 | G12: =SUM(Process!O73:P124) -> 12.927094 | H12: =G12/$G$15 -> 0.36761757 | I12: =Volume!B58/Parameter!$P$4 -> 2437.5631 | J12: 36.44571 | K12: =I12/G12/Parameter!$P$6/Parameter!$P$7 -> 27.729756 | L12: =K12/E12 -> 1.4518197 | M12: =B12*9.2*($B$21*$B$20+(1-$B$21)) -> 302.68 | N12: =D12/M12 -> 27.325889
A13: Packing | B13: 24 | C13: =B13/$B$15 -> 0.25531915 | E13: 37.5 | F13: 10.446309 | G13: =SUM(Process!P125:P149) -> 9.0936252 | H13: =G13/$G$15 -> 0.25860231 | J13: 34.315006 | K13: =I12/G13/Parameter!$P$6/Parameter!$P$7 -> 39.419391 | L13: =K13/E13 -> 1.0511838
A14: Sub. Outbound | B14: 71 | C14: =SUM(C12:C13) -> 0.75531915 | D14: / | E14: 12.7 | G14: =SUM(G12:G13) -> 22.020719 | H14: =SUM(H12:H13) -> 0.62621989 | I14: / | K14: =I12/G14/Parameter!$P$6/Parameter!$P$7 -> 16.27854 | L14: =K14/E14 -> 1.2817748
A15: Overall DC (incl. inventory) | B15: 94 | C15: =C11+C14 -> 0.94680851 | D15: =D9+D12 -> 9412 | E15: 10.9 | F15: 32.728489 | G15: =SUM(G11,G14,Process!P152:P164) -> 35.164516 | H15: =H11+H14 -> 0.96213494 | I15: =I9+I12 -> 3188.1058 | J15: 14.325106 | K15: =I15/G15/Parameter!$P$6/Parameter!$P$7 -> 13.332732 | L15: =K15/E15 -> 1.2231865
G16: =G10-F10 -> 0.69720998
G17: =G12-F12 -> 3.0915012
G18: =G13-F13 -> -1.3526842
A20: Assume warehouse space comparison % | B20: 0.5
A21: Assume space/distance impact on the productivity | B21: 0.6
A25: Name | B25: Net workload | C25: Volume | D25: Unit | E25: Share
A26: 1-A Full pallets unloading - 40' trailers (seafreight) | B26: 117.0202 | C26: 6755.651 | D26: order lines | E26: 0.01932927 | F26: =SUM(E26:E31) -> 0.18804948 | G26: Receiving
A27: 1-B Bulk unloading with pallet - truck (airfreight) | B27: 24.638365 | C27: 15077.682 | D27: order lines | E27: 0.0038160784
A28: 2-A Sorting (Full Package) | B28: 29.784326 | C28: 4252.0339 | D28: order lines | E28: 0.0054244929
A29: 2-B Sorting (Mixed Package) | B29: 842.91319 | C29: 14416.08 | D29: order lines | E29: 0.12722453
A30: 2-C Sorting (Bulk Package) | B30: 212.49636 | C30: 3165.2199 | D30: order lines | E30: 0.032255109
A31: 2-D Sorting (X-docking) | B31: 0 | C31: 0 | D31: order lines | E31: 0
A32: 3-A Put away in Mezzanine with RF | B32: 82.485411 | C32: 14416.08 | D32: order lines | E32: 0.011963865 | F32: =SUM(E32:E37) -> 0.079471444 | G32: Putaway
A33: 3-B Put away in racks and cantilevers with RF | B33: 459.1067 | C33: 7308.0871 | D33: order lines | E33: 0.066816648
A34: 3-C Put away in floor storage area with RF | B34: 4.7474837 | C34: 109.16667 | D34: order lines | E34: 0.00069093077
A35: 3-D Put away in Locked room with RF | B35: 0 | C35: 0 | D35: order lines | E35: 0
A36: 3-E Put away in DG area with RF | B36: 0 | C36: 0 | D36: order lines | E36: 0
A37: 3-F Put away in X-dock area with RF | B37: 0 | C37: 0 | D37: order lines | E37: 0
A38: 4-A Mixed cases prep. with RF, picking from Mezzanine/Carousel, manual case building | B38: 1459.4318 | C38: 40607.125 | D38: order lines | E38: 0.23235286 | F38: =SUM(E38:E42,E46) -> 0.43872334 | G38: Picking
A39: 4-B Picking from Floor with RF | B39: 16.523335 | C39: 307.5 | D39: order lines | E39: 0.002417094
A40: 4-C Picking from Racking/Cantilever, with RF | B40: 1193.4923 | C40: 20585.375 | D40: order lines | E40: 0.17445232
A41: 4-D Mixed cases prep. with RF, picking from Locked area, manual case building | B41: 0 | C41: 0 | D41: order lines | E41: 0
A42: 4-E Picking from Racking in DG room, with RF | B42: 0 | C42: 0 | D42: order lines | E42: 0
A43: 5 Packing | B43: 1623.9572 | C43: 61500 | D43: order lines | E43: 0.23884155 | F43: =SUM(E43:E44) -> 0.24373543 | G43: Packing
A44: 6 Loading pallets | B44: 32.075329 | C44: 61500 | D44: order lines | E44: 0.0048938762
A45: 7 Inventory per location with RF | B45: 137.74186 | C45: 4371.7667 | D45: location | E45: 0.026112593
...

Sheet Rate sheet
B4: PCN Warehousing Quotation Sheet
B6: 1.1. Storage Systems
C7: This quotation covers all the costs incurred for storage infrastructure installation, equipment & maintanence, etc
C11: Additional Storage System (Racking and Shelving) | J11: Racking brand: OTL | T11: Remarks
T12: The quotation only refers to new racking setup in future
C13: a) Pallet Racking | F13: RMB per large parts location (avg. 1900*1300*1700mm) per Month
F15: RMB per medium parts location (avg. 1300*800*520*) per Month
C17: b) Shelves | F17: RMB per modules (300mm depth) per Month, including all accessories like shelves, dividers or boxes, etc
F19: RMB per modules (600mm depth) per Month, including all accessories like shelves, dividers or boxes, etc
F21: RMB per modules (1000mm depth) per Month, including all accessories like shelves, dividers or boxes, etc
C23: The pallet location size mentioned above is for reference only, there may be 20% deviation in actual
C24: Shelves is set up to 2.5m high for each floor in warehouse, and levelers and dividers qty. depends on actual requirements
B26: 1.2. Operation
C27: This quotation covers all the costs incurred for warehouse processing (inbound, outbound, special handling), include payments for all services that are not included under Section 1.1 & 1.3
D29: 有些流程可以不分配mhe, 手动改报价，看P&L；例如：labelling | J29: From cost allocation
C30: a) Inbound Processing | E30: ='Cost Allocation'!U12 -> 8.1632846 | F30: RMB per inbound order line | J30: ='Cost Allocation'!U12 -> 8.1632846 | T30: Remark
C31: b) Inbound DG Processing | E31: 0 | F31: RMB per inbound order line | T31: All the cost which is not related to warehouse storage equipment should be covered in Operation cost.
C33: c) Outbound Processing | E33: ='Cost Allocation'!U14 -> 6.5369352 | F33: RMB per outbound order line | J33: ='Cost Allocation'!U14 -> 6.5369352
C34: d) Outbound DG Processing | E34: 0 | F34: RMB per outbound order line
C36: e) Warrenty & Return | E36: ='Cost Allocation'!U15 -> 23.523858 | F36: RMB per processed line | J36: ='Cost Allocation'!U15 -> 23.523858
C37: f) Warrenty & Return DG | E37: ='Cost Allocation'!U16 -> 26.812908 | F37: RMB per processed line | J37: ='Cost Allocation'!U16 -> 26.812908
C39: g) Key cutting handling | E39: ='Cost Allocation'!U13 -> 45.028662 | F39: RMB per key piece | J39: ='Cost Allocation'!U13 -> 45.028662
C41: h) Chinese labelling | E41: 0.15 | F41: RMB per label pieces | J41: ='Cost Allocation'!U7 -> 0.25057427
C43: i) Engraved steal seal | E43: ='Cost Allocation'!U10 -> 45.028662 | F43: RMB per piece | J43: ='Cost Allocation'!U10 -> 45.028662
C45: j) Customs inspection | E45: ='Cost Allocation'!U9 -> 8.9376361 | F45: RMB per inbound lines | J45: ='Cost Allocation'!U9 -> 8.9376361
B47: 1.3 Customer care service
C48: h) Customer care service | F48: RMB per position
B50: 1.3 Start-up cost
T51: Remark
C52: Charged items | F52: Note | O52: Expenses | T52: This quotation covers all the services of SP's responsibilities that have listed in the Matrix of Responsibilities (point 6) Any other cost that may incurred during the warehouse start-up phase should also be invloved, like office renovation, security, trainning, handover, etc.
C53: =Startup!B2 -> 1. Pre- on board and training | F53: Including DC manager/supervisor will pre-on board 2 weeks and operators 1 week for traning | O53: =Startup!D2 -> 58704.605
C54: =Startup!B18 -> 2. Stock count for handover | F54: Stock count with current vendor and confirm handover | O54: =Startup!D18 -> 53478.967
C55: 3. Office setup | F55: 3PL's office setup cost | O55: ='MHE&INV list'!K30*(1+'Cost Allocation'!R4) -> 457600
C56: 4. Security system | O56: ='MHE&INV list'!K26*(1+'Cost Allocation'!R4) -> 644644
B60: Tax rate (%): | E60: (Tax type shall be VAT, if not, please specify) | I60: (bidder to fill up)

Sheet P&L Sheet
C2: Subsequent Years Costs
C4: Yr1 | D4: Yr2 | E4: Yr3 | F4: Yr4 | G4: Yr5 | H4: Yr6 | I4: Yr7 | J4: Yr8 | K4: Yr9 | L4: Yr10 | M4: Total
B5: ='Rate sheet'!C30 -> a) Inbound Processing | C5: ='Rate sheet'!$E$30*Volume!B7 -> 1687469 | D5: ='Rate sheet'!$E$30*Volume!C7 -> 1636844.9 | E5: ='Rate sheet'!$E$30*Volume!D7 -> 1587739.5 | F5: ='Rate sheet'!$E$30*Volume!E7 -> 1635371.7 | G5: ='Rate sheet'!$E$30*Volume!F7 -> 1684432.9 | M5: =SUM(C5:L5) -> 8231858 | N5: =M5/$M$19 -> 0.22433791
B6: ='Rate sheet'!C31 -> b) Inbound DG Processing | C6: ='Rate sheet'!$E$31*Volume!B8 -> 0 | D6: ='Rate sheet'!$E$31*Volume!C8 -> 0 | E6: ='Rate sheet'!$E$31*Volume!D8 -> 0 | F6: ='Rate sheet'!$E$31*Volume!E8 -> 0 | G6: ='Rate sheet'!$E$31*Volume!F8 -> 0 | M6: =SUM(C6:L6) -> 0 | N6: =M6/$M$19 -> 0
B7: ='Rate sheet'!C33 -> c) Outbound Processing | C7: ='Rate sheet'!$E$33*Volume!B56 -> 4575344 | D7: ='Rate sheet'!$E$33*Volume!C56 -> 4438083.7 | E7: ='Rate sheet'!$E$33*Volume!D56 -> 4304941.1 | F7: ='Rate sheet'!$E$33*Volume!E56 -> 4434089.4 | G7: ='Rate sheet'!$E$33*Volume!F56 -> 4567112.1 | M7: =SUM(C7:L7) -> 22319570 | N7: =M7/$M$19 -> 0.60826193
B8: ='Rate sheet'!C34 -> d) Outbound DG Processing | C8: ='Rate sheet'!$E$37*Volume!B57 -> 382998.8 | D8: ='Rate sheet'!$E$37*Volume!C57 -> 371508.83 | E8: ='Rate sheet'!$E$37*Volume!D57 -> 360363.57 | F8: ='Rate sheet'!$E$37*Volume!E57 -> 371174.48 | G8: ='Rate sheet'!$E$37*Volume!F57 -> 382309.71 | M8: =SUM(C8:L8) -> 1868355.4 | N8: =M8/$M$19 -> 0.050917175
B9: ='Rate sheet'!C36 -> e) Warrenty & Return | C9: ='Rate sheet'!$E$36*Volume!B84 -> 304469.3 | D9: ='Rate sheet'!$E$36*Volume!C84 -> 295335.22 | E9: ='Rate sheet'!$E$36*Volume!D84 -> 286475.16 | F9: ='Rate sheet'!$E$36*Volume!E84 -> 295069.42 | G9: ='Rate sheet'!$E$36*Volume!F84 -> 303921.5 | M9: =SUM(C9:L9) -> 1485270.6 | N9: =M9/$M$19 -> 0.040477193
B10: ='Rate sheet'!C37 -> f) Warrenty & Return DG | C10: ='Rate sheet'!$E$37*Volume!B84*Volume!$J$26 -> 20822.368 | D10: ='Rate sheet'!$E$37*Volume!C84*Volume!$J$26 -> 20197.697 | E10: ='Rate sheet'!$E$37*Volume!D84*Volume!$J$26 -> 19591.766 | F10: ='Rate sheet'!$E$37*Volume!E84*Volume!$J$26 -> 20179.519 | G10: ='Rate sheet'!$E$37*Volume!F84*Volume!$J$26 -> 20784.905 | M10: =SUM(C10:L10) -> 101576.26 | N10: =M10/$M$19 -> 0.0027681971
B11: ='Rate sheet'!C39 -> g) Key cutting handling | C11: ='Rate sheet'!$E$39*Volume!B87 -> 129682.55 | D11: ='Rate sheet'!$E$39*Volume!C87 -> 125765.05 | E11: ='Rate sheet'!$E$39*Volume!D87 -> 116984.46 | F11: ='Rate sheet'!$E$39*Volume!E87 -> 111130.74 | G11: ='Rate sheet'!$E$39*Volume!F87 -> 105547.18 | M11: =SUM(C11:L11) -> 589109.98 | N11: =M11/$M$19 -> 0.016054663
B12: ='Rate sheet'!C41 -> h) Chinese labelling | C12: ='Rate sheet'!$E$41*Volume!B85 -> 296497.8 | D12: ='Rate sheet'!$E$41*Volume!C85 -> 287602.87 | E12: ='Rate sheet'!$E$41*Volume!D85 -> 278974.78 | F12: ='Rate sheet'!$E$41*Volume!E85 -> 287344.02 | G12: ='Rate sheet'!$E$41*Volume!F85 -> 295964.34 | M12: =SUM(C12:L12) -> 1446383.8 | N12: =M12/$M$19 -> 0.039417435
B13: ='Rate sheet'!C43 -> i) Engraved steal seal | C13: ='Rate sheet'!E43*第二轮数据!C60 -> 540.34394 | D13: =C13 -> 540.34394 | E13: =D13 -> 540.34394 | F13: =E13 -> 540.34394 | G13: =F13 -> 540.34394 | M13: =SUM(C13:L13) -> 2701.7197 | N13: =M13/$M$19 -> 7.3628355e-05
B14: ='Rate sheet'!C45 -> j) Customs inspection | C14: ='Rate sheet'!$E$45*Volume!B86 -> 16087.745 | D14: ='Rate sheet'!$E$45*Volume!C86 -> 15605.113 | E14: ='Rate sheet'!$E$45*Volume!D86 -> 15131.418 | F14: ='Rate sheet'!$E$45*Volume!E86 -> 15891.117 | G14: ='Rate sheet'!$E$45*Volume!F86 -> 16686.567 | M14: =SUM(C14:L14) -> 79401.959 | N14: =M14/$M$19 -> 0.0021638942
B15: Startup | C15: {='Rate sheet'!O53:P53+'Rate sheet'!O54:P54+'Rate sheet'!O55:P55} -> 569783.57 | D15: 0 | M15: =SUM(C15:L15) -> 569783.57 | N15: =M15/$M$19 -> 0.015527972
B16: Packaging | M16: =SUM(C16:L16) -> 0 | N16: =M16/$M$19 -> 0
M17: =SUM(C17:L17) -> 0 | N17: =M17/$M$19 -> 0
M18: =SUM(C18:L18) -> 0 | N18: =M18/$M$19 -> 0
B19: Total Rev. | C19: =SUM(C5:C18) -> 7983695.4 | D19: =SUM(D5:D18) -> 7191483.7 | E19: =SUM(E5:E18) -> 6970742.2 | F19: =SUM(F5:F18) -> 7170790.7 | G19: =SUM(G5:G18) -> 7377299.5 | H19: =SUM(H5:H18) -> 0 | I19: =SUM(I5:I18) -> 0 | J19: 0 | K19: 0 | L19: 0 | M19: =SUM(C19:L19) -> 36694012
B21: DIRECT COST
B22: Labour/Management | C22: =SUM(C23:C24) -> 4729186 | D22: =SUM(D23:D24) -> 4897287.9 | E22: =SUM(E23:E24) -> 4894762.8 | F22: =SUM(F23:F24) -> 4994782.5 | G22: =SUM(G23:G24) -> 5202365.6 | H22: =SUM(H23:H26) -> 0 | I22: =SUM(I23:I26) -> 0 | J22: 0 | K22: 0 | L22: 0 | M22: =SUM(C22:K22) -> 24718385
B23: Direct | C23: =SUM(Process!AB:AB) -> 3319786 | D23: =SUM(Process!AC:AC) -> 3445605.9 | E23: =SUM(Process!AD:AD) -> 3399530.4 | F23: =SUM(Process!AE:AE) -> 3454693.1 | G23: =SUM(Process!AF:AF) -> 3616073.4 | H23: =$P$23*W23 -> 0 | I23: =$P$23*X23 -> 0 | J23: 0 | K23: 0 | L23: 0 | M23: =SUM(C23:L23) -> 17235689
B24: Indirect | C24: =SUM(Parameter!V19:V22) -> 1409400 | D24: =SUM(Parameter!W19:W22) -> 1451682 | E24: =SUM(Parameter!X19:X22) -> 1495232.5 | F24: =SUM(Parameter!Y19:Y22) -> 1540089.4 | G24: =SUM(Parameter!Z19:Z22) -> 1586292.1 | H24: =$P$23*W24 -> 0 | I24: =$P$23*X24 -> 0 | J24: 0 | K24: 0 | L24: 0 | M24: =SUM(C24:L24) -> 7482696
B26: Gross margin
B28: Equipment | C28: =C29+C30 -> 2741746.1 | D28: =D29+D30 -> 1706584 | E28: =E29+E30 -> 1700317.3 | F28: =F29+F30 -> 1561161.8 | G28: =G29+G30 -> 1555929.8 | H28: 0 | I28: 0 | J28: 0 | K28: 0 | L28: 0 | M28: =SUM(C28:L28) -> 9265739.1
B29: Lease/ Consume | C29: =SUMIF('MHE&INV list'!$B:$B,"Lease/Consume",'MHE&INV list'!K:K) -> 1577782.7 | D29: =SUMIF('MHE&INV list'!$B:$B,"Lease/Consume",'MHE&INV list'!L:L) -> 1571625.8 | E29: =SUMIF('MHE&INV list'!$B:$B,"Lease/Consume",'MHE&INV list'!M:M) -> 1566393.8 | F29: =SUMIF('MHE&INV list'!$B:$B,"Lease/Consume",'MHE&INV list'!N:N) -> 1561161.8 | G29: =SUMIF('MHE&INV list'!$B:$B,"Lease/Consume",'MHE&INV list'!O:O) -> 1555929.8 | H29: 0 | I29: 0 | J29: 0 | K29: 0 | L29: 0 | M29: =SUM(C29:L29) -> 7832893.8
B30: Depreciation | C30: =SUMIF('MHE&INV list'!$B:$B,"Purchase",'MHE&INV list'!K:K) -> 1163963.5 | D30: =SUMIF('MHE&INV list'!$B:$B,"Purchase",'MHE&INV list'!L:L) -> 134958.22 | E30: =SUMIF('MHE&INV list'!$B:$B,"Purchase",'MHE&INV list'!M:M) -> 133923.53 | F30: =SUMIF('MHE&INV list'!$B:$B,"Purchase",'MHE&INV list'!N:N) -> 0 | G30: =SUMIF('MHE&INV list'!$B:$B,"Purchase",'MHE&INV list'!O:O) -> 0 | H30: 0 | I30: 0 | J30: 0 | K30: 0 | L30: 0 | M30: =SUM(C30:L30) -> 1432845.2
M31: =SUM(C31:L31) -> 0
B32: Occupancy/Warehouse Facility Costs | C32: =C34 -> 0 | D32: =D34 -> 0 | E32: =E34 -> 0 | F32: =F34 -> 0 | G32: =G34 -> 0 | H32: =H34 -> 0 | I32: =I34 -> 0 | J32: 0 | K32: 0 | L32: 0 | M32: =SUM(C32:L32) -> 0
B33: Rent | C33: 0 | D33: 0 | E33: 0 | F33: 0 | G33: 0 | H33: 0 | I33: 0 | J33: 0 | K33: 0 | L33: 0 | M33: =SUM(C33:L33) -> 0
B34: Other | C34: 0 | D34: 0 | E34: 0 | F34: 0 | G34: 0 | H34: 0 | I34: 0 | J34: 0 | K34: 0 | L34: 0 | M34: =SUM(C34:L34) -> 0
M35: =SUM(C35:L35) -> 0
B36: Packaging | C36: 0 | D36: 0 | E36: 0 | F36: 0 | G36: 0 | H36: 0 | I36: 0 | J36: 0 | K36: 0 | L36: 0 | M36: =SUM(C36:L36) -> 0
M37: =SUM(C37:L37) -> 0
B38: Start up | C38: =Startup!D2+Startup!D18+Startup!D32 -> 387360.43 | D38: 0 | E38: 0 | F38: 0 | G38: 0 | H38: 0 | I38: 0 | J38: 0 | K38: 0 | L38: 0 | M38: =SUM(C38:L38) -> 387360.43
M39: =SUM(C39:L39) -> 0
M40: =SUM(C40:L40) -> 0
M41: =SUM(C41:L41) -> 0
M42: =SUM(C42:L42) -> 0
M43: =SUM(C43:L43) -> 0
B44: Total Costs | C44: =C38+C36+C32+C28+C22 -> 7858292.6 | D44: =D38+D36+D32+D28+D22 -> 6603871.9 | E44: =E38+E36+E32+E28+E22 -> 6595080.2 | F44: =F38+F36+F32+F28+F22 -> 6555944.3 | G44: =G38+G36+G32+G28+G22 -> 6758295.4 | H44: =H38+H36+H32+H28+H22 -> 0 | I44: =I38+I36+I32+I28+I22 -> 0 | J44: =J38+J36+J32+J28+J22 -> 0 | ... M44: =M38+M36+M32+M28+M22 -> 34371484
B45: Total Rev. - Total Costs | C45: =C19-C44 -> 125402.83 | D45: =D19-D44 -> 587611.75 | E45: =E19-E44 -> 375662.04 | F45: =F19-F44 -> 614846.42 | G45: =G19-G44 -> 619004.14 | H45: =H19-H44 -> 0 | I45: =I19-I44 -> 0 | J45: 0 | K45: 0 | L45: 0 | M45: =SUM(C45:L45) -> 2322527.2
...

Sheet Cost Allocation
A1: (ALL COST IS ANNUAL COST)
B3: Profit （%） | N3: Profit （%） | O3: Profit （%） | Q3: Profit （%） | R3: Profit （%）
B4: 0.1 | N4: 0.1 | O4: 0.1 | Q4: 0.1 | R4: 0.1
E5: 求和项:FTE | F5: 列标签 | N5: MHE | O5: Packing | P5: Charge FTE+MHE | Q5: Charge Indirect Labor | R5: Other inv. | S5: Total Charge | T5: Annual Volume | U5: Unit rate
A6: 行标签 | B6: FTE cost (Y1) | C6: %WorkLoad | D6: % (adjust) | E6: 行标签 | F6: CB | G6: CB - DG | H6: Manual | I6: OP-move | J6: OP-raise/down | K6: Rider on | L6: R-Truck | M6: Trolley | N6: (Y1) | P6: (Y1) | Q6: (Y1) | R6: (Y1) | S6: (Y1) | T6: (Y1) | U6: (Y1)
A7: Chinese labelling | B7: 206448.15 | C7: 0.065891632 | D7: =C7/(1-$C$8) -> 0.068508681 | E7: Chinese labelling | F7: 0.020665526 | G7: 0 | H7: 0.12345472 | I7: 0 | J7: 0 | K7: 0 | L7: 0 | M7: 0 | N7: =SUMPRODUCT(F7:M7,$F$22:$M$22) -> 4265.3645 | P7: =$P$18*D7 -> 316722.04 | Q7: =D7*$Q$18 -> 106211.75 | R7: =$R$18*D7 -> 72364.332 | S7: =P7+Q7+R7 -> 495298.13 | T7: =Volume!B85 -> 1976652 | U7: =S7/T7 -> 0.25057427
A8: Count | B8: 135524.91 | C8: 0.038200254 | E8: Count | F8: 0.00085405103 | G8: 0.008722168 | H8: 0.05715381 | I8: 0 | J8: 0.10694336 | K8: 0.023448853 | L8: 0 | M8: 0.00087520169 | N8: =SUMPRODUCT(F8:M8,$F$22:$M$22) -> 14960.915 | P8: =$P$18*D8 -> 0 | Q8: =D8*$Q$18 -> 0 | R8: =$R$18*D8 -> 0 | S8: =P8+Q8+R8 -> 0
A9: Customs inspection | B9: 9491.2114 | C9: 0.0021402216 | D9: =C9/(1-$C$8) -> 0.0022252258 | E9: Customs inspection | F9: 0 | G9: 0 | H9: 0.0041520117 | I9: 0 | J9: 0 | K9: 0 | L9: 0 | M9: 0 | N9: =SUMPRODUCT(F9:M9,$F$22:$M$22) -> 0 | P9: =$P$18*D9 -> 10287.427 | Q9: =D9*$Q$18 -> 3449.8566 | R9: =$R$18*D9 -> 2350.461 | S9: =P9+Q9+R9 -> 16087.745 | T9: =Volume!B86 -> 1800 | U9: =S9/T9 -> 8.9376361
A10: Engraved steal seal | B10: 255.02734 | C10: 7.188427e-05 | D10: =C10/(1-$C$8) -> 7.4739331e-05 | E10: Engraved steal seal | F10: 0 | G10: 0 | H10: 0.00013286437 | I10: 0 | J10: 0 | K10: 0 | L10: 0 | M10: 3.1877215e-05 | N10: =SUMPRODUCT(F10:M10,$F$22:$M$22) -> 0.12865337 | P10: =$P$18*D10 -> 345.52692 | Q10: =D10*$Q$18 -> 115.87137 | R10: =$R$18*D10 -> 78.945642 | S10: =P10+Q10+R10 -> 540.34394 | T10: =第二轮数据!C60 -> 12 | U10: =S10/T10 -> 45.028662
A11: Inbound DG processing | C11: 0 | D11: =C11/(1-$C$8) -> 0 | E11: Inbound DG processing | F11: 0 | G11: 0 | H11: 0 | I11: 0 | J11: 0 | K11: 0 | L11: 0 | M11: 0 | N11: =SUMPRODUCT(F11:M11,$F$22:$M$22) -> 0 | P11: =$P$18*D11 -> 0 | Q11: =D11*$Q$18 -> 0 | R11: =$R$18*D11 -> 0 | S11: =P11+Q11+R11 -> 0 | T11: =Volume!B8 -> 13194.54 | U11: =S11/T11 -> 0
A12: Inbound processing | B12: 777532.98 | C12: 0.22449123 | D12: =C12/(1-$C$8) -> 0.23340745 | E12: Inbound processing | F12: 0.50886175 | G12: 0.62636912 | H12: 0.058743661 | I12: 0 | J12: 0.31828581 | K12: 0 | L12: 1 | M12: 0.21202593 | N12: =SUMPRODUCT(F12:M12,$F$22:$M$22) -> 443532.29 | P12: =$P$18*D12 -> 1079064.5 | Q12: =D12*$Q$18 -> 361860.91 | R12: =$R$18*D12 -> 246543.56 | S12: =P12+Q12+R12 -> 1687469 | T12: =Volume!B7 -> 206714.46 | U12: =S12/T12 -> 8.1632846
A13: Key cutting handling | B13: 61206.563 | C13: 0.017252225 | D13: =C13/(1-$C$8) -> 0.017937439 | E13: Key cutting handling | F13: 0 | G13: 0 | H13: 0.03188745 | I13: 0 | J13: 0 | K13: 0 | L13: 0 | M13: 0.0076505316 | N13: =SUMPRODUCT(F13:M13,$F$22:$M$22) -> 30.876808 | P13: =$P$18*D13 -> 82926.462 | Q13: =D13*$Q$18 -> 27809.13 | R13: =$R$18*D13 -> 18946.954 | S13: =P13+Q13+R13 -> 129682.55 | T13: =Volume!B87 -> 2880 | U13: =S13/T13 -> 45.028662
A14: Outbound processing | B14: 1939873.3 | C14: 0.60867761 | D14: =C14/(1-$C$8) -> 0.63285275 | E14: Outbound processing | F14: 0.46961867 | G14: 0.36490871 | H14: 0.64052246 | I14: 1 | J14: 0.57477083 | K14: 0.97655115 | L14: 0 | M14: 0.77941646 | N14: =SUMPRODUCT(F14:M14,$F$22:$M$22) -> 366366.33 | O14: =SUM('MHE&INV list'!K13:K14,'MHE&INV list'!K20:K25)*C14/(C15+C14) -> 50509.281 | P14: =$P$18*D14 -> 2925737.5 | Q14: =D14*$Q$18 -> 981136.93 | R14: =$R$18*D14 -> 668469.54 | S14: =P14+Q14+R14 -> 4575344 | T14: =Volume!B56 -> 699921.88 | U14: =S14/T14 -> 6.5369352
A15: Warranty & Return | B15: 179626.32 | C15: 0.040504855 | D15: =C15/(1-$C$8) -> 0.042113605 | E15: Warranty & Return | F15: 0 | G15: 0 | H15: 0.078579073 | I15: 0 | J15: 0 | K15: 0 | L15: 0 | M15: 0 | N15: =SUMPRODUCT(F15:M15,$F$22:$M$22) -> 0 | O15: =SUM('MHE&INV list'!K13:K14,'MHE&INV list'!K20:K25)*C15/(C15+C14) -> 3361.1735 | P15: =$P$18*D15 -> 194695.14 | Q15: =D15*$Q$18 -> 65290.407 | R15: =$R$18*D15 -> 44483.749 | S15: =P15+Q15+R15 -> 304469.3 | T15: =Volume!B84 -> 12943 | U15: =S15/T15 -> 23.523858
A16: Warranty & Return DG | B16: 9827.58 | C16: 0.0027700889 | D16: =C16/(1-$C$8) -> 0.0028801098 | E16: Warranty & Return DG | F16: 0 | G16: 0 | H16: 0.0053739488 | I16: 0 | J16: 0 | K16: 0 | L16: 0 | M16: 0 | N16: =SUMPRODUCT(F16:M16,$F$22:$M$22) -> 0 | P16: =$P$18*D16 -> 13315.017 | Q16: =D16*$Q$18 -> 4465.1494 | R16: =$R$18*D16 -> 3042.2017 | S16: =P16+Q16+R16 -> 20822.368 | T16: =T15*Volume!J26 -> 776.58 | U16: =S16/T16 -> 26.812908
A17: Outbound DG processing | C17: 0 | D17: =C17/(1-$C$8) -> 0 | E17: Outbound DG processing | F17: 0 | G17: 0 | H17: 0 | I17: 0 | J17: 0 | K17: 0 | L17: 0 | M17: 0 | N17: =SUMPRODUCT(F17:M17,$F$22:$M$22) -> 0 | P17: =$P$18*D17 -> 0 | Q17: =D17*$Q$18 -> 0 | R17: =$R$18*D17 -> 0 | S17: =P17+Q17+R17 -> 0 | T17: 0 | U17: 0
A18: 总计 | B18: 3319786 | C18: 1 | D18: =SUM(D7:D17) -> 1 | E18: 总计 | F18: 1 | G18: 1 | H18: 1 | I18: 1 | J18: 1 | K18: 1 | L18: 1 | M18: 1 | N18: =SUM(N7:N17) -> 829155.9 | O18: =SUM(O7:O17) -> 53870.454 | P18: =N18*(1+$B$4)+O18*(1+$N$4)+B18*(1+$O$4) -> 4623093.6 | Q18: =SUM(Parameter!V19:V22)*(1+Q4) -> 1550340 | R18: =SUM('MHE&INV list'!K25:K53)*(1+R4)-SUMIF('MHE&INV list'!A:A,"Startup",'MHE&INV list'!K:K) -> 1056279.8 | S18: =R18+P18+Q18 -> 7229713.4 | T18: / | U18: /
E22: MHE: Y1 cost | F22: =VLOOKUP(F$6,'MHE&INV list'!$C$2:$K$10,9,0) -> 206400 | G22: =VLOOKUP(G$6,'MHE&INV list'!$C$2:$K$10,9,0) -> 120000 | I22: =VLOOKUP(I$6,'MHE&INV list'!$C$2:$K$10,9,0) -> 41520 | J22: =VLOOKUP(J$6,'MHE&INV list'!$C$2:$K$10,9,0) -> 100800 | K22: =VLOOKUP(K$6,'MHE&INV list'!$C$2:$K$10,9,0) -> 126000 | L22: =VLOOKUP(L$6,'MHE&INV list'!$C$2:$K$10,9,0) -> 230400 | M22: =VLOOKUP(M$6,'MHE&INV list'!$C$2:$K$10,9,0) -> 4035.9036
B36: Chinese labelling
B37: Count
B38: Customs inspection
B39: Engraved steal seal
B40: Inbound DG processing
B41: Inbound processing
B42: Key cutting handling
B43: Outbound processing
B44: Warranty & Return
B45: Warranty & Return DG
B46: Outbound DG processing

Sheet Volume
A2: 1. Inbound | M2: assumptions
B3: Start from 2026, Aug | M3: given
A4: Delivery lines inbound to PDC Shanghai | B4: 2026 | C4: 2027 | D4: 2028 | E4: 2029 | F4: 2030 | M4: calculation
A5: VOR | B5: =B7-B6 -> 28940.024 | C5: =C7-C6 -> 28071.824 | D5: =D7-D6 -> 27229.669 | E5: =E7-E6 -> 28046.559 | F5: =F7-F6 -> 28887.956
A6: VOL | B6: =B7*第二轮数据!$C$10 -> 177774.44 | C6: =C7*第二轮数据!$C$10 -> 172441.2 | D6: =D7*第二轮数据!$C$10 -> 167267.97 | E6: =E7*第二轮数据!$C$10 -> 172286.01 | F6: =F7*第二轮数据!$C$10 -> 177454.59
A7: Inbound normal | B7: =B9-B8 -> 206714.46 | C7: =C9-C8 -> 200513.03 | D7: =D9-D8 -> 194497.64 | E7: =E9-E8 -> 200332.56 | F7: =F9-F8 -> 206342.54
A8: Inbound DG lines | B8: =B9*第二轮数据!$C$8 -> 13194.54 | C8: =C9*第二轮数据!$C$8 -> 12798.704 | D8: =D9*第二轮数据!$C$8 -> 12414.743 | E8: =E9*第二轮数据!$C$8 -> 12787.185 | F8: =F9*第二轮数据!$C$8 -> 13170.801
A9: TTL inbound | B9: 219909 | C9: 213311.73 | D9: 206912.38 | E9: 213119.75 | F9: 219513.34
A10: Warranty and Returns&Scrapping (lines per year) | B10: 12943 | C10: 12554.71 | D10: 12178.069 | E10: 12543.411 | F10: 12919.713
A11: Cross Docking | B11: =B7*$H$11 -> 10335.723 | C11: =C7*$H$11 -> 10025.651 | D11: =D7*$H$11 -> 9724.8818 | E11: =E7*$H$11 -> 10016.628 | F11: =F7*$H$11 -> 10317.127 | H11: 0.05 | I11: cross dock vs. total inbound
A13: Freight CBM inbound to PDC Shanghai | B13: 2026 | H13: Total CBM - 2025
A14: Express (VOR) - Air | B14: 6447.8 | H14: =B14+B15 -> 57857.8
A15: Stock (VOL) - Seafreight | B15: 51410
A17: Freight kg inbound to PDC Shanghai | B17: 2026
A18: Express (VOR) - Air | B18: 414579
A19: Stock (VOL) - Seafreight | B19: 2474631
A21: Inbound Trasnportation Shipments Estimation for 2026
A22: Order type | B22: Shipment type | C22: Truck Size | D22: Loading Space | E22: Shipment Qty | F22: Check | H22: Total trucks/ cntr. - 2026
A23: Stock (VOL) | B23: Seafreight | C23: 40 HQ | E23: 678 | F23: 57.6 | H23: =SUM(E23:E31) -> 1408
A24: Stock (VOL) DG | B24: Seafreight | C24: 40 HQ | E24: 108 | F24: =F23 -> 57.6
A25: Stock (VOL) | B25: Seafreight | C25: 40 HQ | E25: 7 | F25: =F24 -> 57.6 | H25: DG - CBM | I25: DG - % in CBM | J25: DG - % in line
A26: Stock (VOL) DG | B26: Seafreight | C26: 40 HQ | E26: 2 | F26: =F25 -> 57.6 | H26: =(E26+E24)*F24+SUMPRODUCT(E29:E31,F29:F31) -> 9286 | I26: =H26/(B14+B15) -> 0.16049694 | J26: =第二轮数据!C50 -> 0.06
A27: Express (VOR) | B27: Airfreight | C27: 4.2M | D27: 10 cbm | E27: 110 | F27: 10
A28: Express (VOR) | B28: Airfreight | C28: 7.2M | D28: 30 cbm | E28: 266 | F28: 30
A29: Express (VOR) DG | B29: Airfreight | C29: 4.2M | D29: 10 cbm | E29: 203 | F29: 10
A30: Express (VOR) DG | B30: Airfreight | C30: 7.2M | D30: 30 cbm | E30: 29 | F30: 30
A31: Express (VOR) DG | B31: Airfreight | C31: 4.2M | D31: 10 cbm | E31: 5 | F31: 10
F32: =SUMPRODUCT(E23:E31,F23:F31) -> 57822 | G32: =F32-H14 -> -35.8
A33: 1.1 Inbound delivery line ratio depending on storage area
A35: Storage Area | B35: Dangerous Goods | C35: Floor Storage | D35: Locked / Lifestyle | E35: Mezzanine | F35: New Parts | G35: Pallet Racking | H35: Cross-Docking | I35: Coding | J35: Check
A36: Inbound (VOR + VOL) | B36: =第二轮数据!C8 -> 0.06 | C36: 0.3 | D36: 0 | E36: =第二轮数据!C16 -> 0.14 | F36: 0 | G36: 0.48 | H36: 0.02 | I36: 0 | J36: =SUM(B36:I36) -> 1
J37: =SUM(B37:I37) -> 0
J38: =SUM(B38:I38) -> 0
A40: Cal. Put away to zones by order type (lines)
A42: Storage Area | B42: Dangerous Goods | C42: Floor Storage | D42: Locked / Lifestyle | E42: Mezzanine | F42: New Parts | G42: Pallet Racking | H42: Cross-Docking | I42: Coding
A43: =A36 -> Inbound (VOR + VOL) | B43: =$B$7*B36 -> 12402.868 | C43: =$B$7*C36 -> 62014.338 | D43: =$B$7*D36 -> 0 | E43: =$B$7*E36 -> 28940.024 | F43: =$B$7*F36 -> 0 | G43: =$B$7*G36 -> 99222.941 | H43: =$B$7*H36 -> 4134.2892 | I43: =$B$7*I36 -> 0
A44: =A37 -> 0 | B44: =$B$6*B37 -> 0 | C44: =$B$6*C37 -> 0 | D44: =$B$6*D37 -> 0 | E44: =$B$6*E37 -> 0 | F44: =$B$6*F37 -> 0 | G44: =$B$6*G37 -> 0 | H44: =$B$6*H37 -> 0 | I44: =$B$6*I37 -> 0
A45: =A38 -> 0 | B45: =$B$10*B38 -> 0 | C45: =$B$10*C38 -> 0 | D45: =$B$10*D38 -> 0 | E45: =$B$10*E38 -> 0 | F45: =$B$10*F38 -> 0 | G45: =$B$10*G38 -> 0 | H45: =$B$10*H38 -> 0 | I45: =$B$10*I38 -> 0
A46: Sub-total lines - inbound | B46: =SUM(B43:B45) -> 12402.868 | C46: =SUM(C43:C45) -> 62014.338 | D46: =SUM(D43:D45) -> 0 | E46: =SUM(E43:E45) -> 28940.024 | F46: =SUM(F43:F45) -> 0 | G46: =SUM(G43:G45) -> 99222.941 | H46: =SUM(H43:H45) -> 4134.2892 | I46: =SUM(I43:I45) -> 0 | J46: =SUM(B46:I46) -> 206714.46
A47: % by put away zone in lines | B47: =B46/$J$46 -> 0.06 | C47: =C46/$J$46 -> 0.3 | D47: =D46/$J$46 -> 0 | E47: =E46/$J$46 -> 0.14 | F47: =F46/$J$46 -> 0 | G47: =G46/$J$46 -> 0.48 | H47: =H46/$J$46 -> 0.02 | I47: =I46/$J$46 -> 0
...

Sheet 第二轮数据
B1: Inbound
B2: unloading - pallet | C2: 0.5
B3: unloading - mix SKU carton | C3: 0.5
B4: inbound orderlines per HU | C4: 2.4
B5: inbound pcs per orderline | C5: 15.19 | E5: 和D19不一样， 用C5
B6: full inspection | C6: 3%-8%
B8: DG rate in overall inbound orderline | C8: 0.06
C9: orderline %
B10: Stock (VOL) | C10: 0.86
B11: Express (VOR) | C11: 0.12
B12: EXPRESS | C12: 0.02 | D12: *这里不懂为什么还有个EXPRSS，建议可以并进VOR
C14: orderline % | D14: pcs/line
B15: Large/Bulky | C15: 0.58 | D15: 4 | F15: 0.3
B16: M2 | C16: 0.14 | D16: 40
B17: M1 | C17: 0.06 | D17: 36 | F17: 0.5
B18: Small | C18: 0.14 | D18: 9
D19: =SUMPRODUCT(C15:C18,D15:D18) -> 11.34
B20: Outbound
B21: DG rate in overall outbound orderline | C21: 0.02
C22: orderline % | E22: Check back
B23: Stock (VOL) | C23: 0.88 | E23: =Parameter!R99 -> 6
B24: Express (VOR) | C24: 0.12 | E24: =Parameter!R94 -> 2
C26: orderline % | E26: check back
B27: Large/Bulky | C27: 0.3 | E27: 1
B28: M2 | C28: 0.27 | E28: =Parameter!R79 -> 6.5
B29: M1 | C29: 0.12 | E29: =E28 -> 6.5
B30: Small | C30: 0.29 | E30: =Parameter!R69 -> 6.5
B32: Outbound pcs per orderline | C32: 4.67 | E32: =SUMPRODUCT(C27:C30,E27:E30) -> 4.72
B33: Outbound orderlines/outbound pack | C33: 5 | E33: =SUMPRODUCT(C23:C24,E23:E24) -> 5.52
B35: Storage
C36: location #
B37: Shelves | C37: 22863 | D37: =C37/SUM($C$37:$C$40) -> 0.59025662
B38: Medium | C38: 8505 | D38: =C38/SUM($C$37:$C$40) -> 0.21957453
B39: Large | C39: 6979 | D39: =C39/SUM($C$37:$C$40) -> 0.18017762
B40: Bulky | C40: 387 | D40: =C40/SUM($C$37:$C$40) -> 0.0099912222
B42: SKU count | C42: 25000
B43: Large/Bulky | C43: 0.23 | D43: 5750
B44: M2 | C44: 0.2 | D44: 5000
B45: M1 | C45: 0.27 | D45: 6750
B46: Small | C46: 0.3 | D46: 7500
...

Sheet Layout 
O9: 187 | P9: Y
O10: 100
O11: 200
O12: 94 | P12: Y
O13: 163 | P13: Y
O14: 243 | P14: Y
O15: 55
O16: 65
O17: 646
O18: 2230
O19: 6561
O20: 115
O21: 55
O22: 1174
O23: 300
O24: 738
O25: 800
O26: 159
... O28: 2470
N30: C3 total | O30: =SUM(O9:O28) -> 22227 | P30: sqm

Sheet Parameter
B2: FACILITY | E2: =E5+J5+J19 -> 28927 | N2: STAFFING
O4: Site working days/year | P4: 293 | V4: [Y(n+1)/Y(n)]
C5: Building | D5: C3 | E5: =SUM(E9:E29) -> 22727 | H5: Building | I5: C2 | J5: =SUM(J9:J17) -> 5200 | O5: Site open time | P5: 8 | V5: Y1 | W5: Y2 | X5: Y3 | Y5: Y4 | Z5: Y5
C6: Nb. Chamber | D6: 4 | E6: =E5/D6 -> 5681.75 | F6: L 60 m x D 90m | H6: Nb. Chamber | I6: 1 | J6: =J5/I6 -> 5200 | K6: L 60 m x D 90m | O6: FTE Working hours/day | P6: 8 | U6: IB+OB growth | V6: 1 | W6: =(Volume!C7+Volume!C56)/(Volume!B7+Volume!B56) -> 0.97 | X6: =(Volume!D7+Volume!D56)/(Volume!C7+Volume!C56) -> 0.97 | Y6: =(Volume!E7+Volume!E56)/(Volume!D7+Volume!D56) -> 1.03 | Z6: =(Volume!F7+Volume!F56)/(Volume!E7+Volume!E56) -> 1.03
O7: Unproductivity rate | P7: 0.85 | U7: Prod. factor | V7: 1 | W7: 1 | X7: 0.98 | Y7: 1 | Z7: 1
C8: No. | D8: Area Name | E8: Space (m2) | F8: Ref. distance (m) | H8: No. | I8: Area Name | J8: Space (m2) | K8: Ref. distance (m) | U8: FTE increase | V8: 1 | W8: =V8*W6*W7 -> 0.97 | X8: =W8*X6*X7 -> 0.922082 | Y8: =X8*Y6*Y7 -> 0.94974446 | Z8: =Y8*Z6*Z7 -> 0.97823679
C9: 1 | D9: QC and return | E9: 187 | H9: 1 | I9: Slow move sto. | J9: 5200 | K9: =SQRT(J9) -> 72.111026
C10: 2 | D10: Home Charging | E10: 100 | O10: Role | P10: TTL. Annual cost | Q10: Salary/month | R10: Company cost % | S10: OT/ year | T10: Annual increase | U10: FTE Qty.-Y1
C11: 3 | D11: Labelling | E11: 200 | O11: Documentation | P11: =Q11*(1+R11)*12+S11 -> 126411.59 | Q11: 7500 | R11: 0.4 | S11: =Q11/(8*20.5)*1.5*6 -> 411.58537 | T11: 1.07 | U11: =SUMIF(Process!O:O,Parameter!O11,Process!P:P) -> 0.29411765 | V11: =SUM(U11:U18) -> 35.176771 | X11: blue collar round up factor
C12: 4 | D12: Cross docking | E12: 94 | O12: IB Planner | P12: =Q12*(1+R12)*12+S12 -> 126068.6 | Q12: 7500 | R12: 0.4 | S12: =Q12/(8*20.5)*1.5 -> 68.597561 | T12: 1.07 | U12: =SUMIF(Process!O:O,Parameter!O12,Process!P:P) -> 2.0395536 | V12: =SUM(U19:U21) -> 5
C13: 5 | D13: Inbound Airfreight | E13: 163 | F13: =SQRT(E13) -> 12.767145 | O13: Inv. Operator | P13: =Q13*(1+R13)*12+S13 -> 100854.88 | Q13: 6000 | R13: 0.4 | S13: =Q13/(8*20.5)*1.5 -> 54.878049 | T13: 1.07 | U13: =SUMIF(Process!O:O,Parameter!O13,Process!P:P) -> 1.3273568 | V13: =V12/V11 -> 0.14213925
C14: 6 | D14: Seafreight Presort | E14: 243 | F14: =SQRT(E14) -> 15.588457 | O14: MHE Driver | P14: =Q14*(1+R14)*12+S14 -> 100854.88 | Q14: 6000 | R14: 0.4 | S14: =Q14/(8*20.5)*1.5 -> 54.878049 | T14: 1.07 | U14: =SUMIF(Process!O:O,Parameter!O14,Process!P:P) -> 11.791417
C15: 7 | D15: PDS Locked Room | E15: 55 | O15: Operator | P15: =Q15*(1+R15)*12+S15 -> 84045.732 | Q15: 5000 | R15: 0.4 | S15: =Q15/(8*20.5)*1.5 -> 45.731707 | T15: 1.07 | U15: =SUMIF(Process!O:O,Parameter!O15,Process!P:P) -> 8.5715752
C16: 8 | D16: Key Cutting Room | E16: 65 | O16: Packer | P16: =Q16*(1+R16)*12+S16 -> 84045.732 | Q16: 5000 | R16: 0.4 | S16: =Q16/(8*20.5)*1.5 -> 45.731707 | T16: 1.07 | U16: =SUMIF(Process!O:O,Parameter!O16,Process!P:P) -> 8.4967736
C17: 9 | D17: Seafreight Unload | E17: 646 | F17: =SQRT(E17) -> 25.41653 | O17: DG operator | P17: =Q17*(1+R17)*12+S17 -> 100854.88 | Q17: 6000 | R17: 0.4 | S17: =Q17/(8*20.5)*1.5 -> 54.878049 | T17: 1.07 | U17: =SUMIF(Process!O:O,Parameter!O17,Process!P:P) -> 2.0465715
C18: 10 | D18: Medium Parts Rack | E18: 2230 | F18: =SQRT(E18) -> 47.222876 | O18: Special handling | P18: =Q18*(1+R18)*12+S18 -> 100854.88 | Q18: 6000 | R18: 0.4 | S18: =Q18/(8*20.5)*1.5 -> 54.878049 | T18: 1.07 | U18: =SUMIF(Process!O:O,Parameter!O18,Process!P:P) -> 0.60940622 | V18: Indirect staffing annual cost
C19: 11 | D19: Large Parts Rack | E19: 6561 | F19: =SQRT(E19) -> 81 | H19: Building | I19: C5 | J19: =SUM(J23:J29) -> 1000 | O19: DC manager | P19: =Q19*(1+R19)*12+S19 -> 435000 | Q19: 25000 | R19: 0.45 | S19: 0 | T19: 1.03 | U19: 1 | V19: =U19*$P19 -> 435000 | W19: =V19*$T19 -> 448050 | X19: =W19*$T19 -> 461491.5 | Y19: =X19*$T19 -> 475336.24 | Z19: =Y19*$T19 -> 489596.33
C20: 12 | D20: Customs inspect | E20: 115 | H20: Nb. Chamber | I20: 1 | J20: =J19/I20 -> 1000 | K20: L 9m x D 11m | O20: Supervisor | P20: =Q20*(1+R20)*12+S20 -> 313200 | Q20: 18000 | R20: 0.45 | S20: 0 | T20: 1.03 | U20: 2 | V20: =U20*$P20 -> 626400 | W20: =V20*$T20 -> 645192 | X20: =W20*$T20 -> 664547.76 | Y20: =X20*$T20 -> 684484.19 | Z20: =Y20*$T20 -> 705018.72 | AA20: 可考虑减少1个Supervisor的配置
C21: 13 | D21: Floor Storage | E21: 555 | F21: =SQRT(E21) -> 23.558438 | O21: Team leader | P21: =Q21*(1+R21)*12+S21 -> 174000 | Q21: 10000 | R21: 0.45 | S21: 0 | T21: 1.03 | U21: =ROUND(SUM(U11:U18)/15,0) -> 2 | V21: =U21*$P21 -> 348000 | W21: =V21*$T21 -> 358440 | X21: =W21*$T21 -> 369193.2 | Y21: =X21*$T21 -> 380269 | Z21: =Y21*$T21 -> 391677.07
C22: 14 | D22: Shelves Area | E22: 1174 | F22: =SQRT(E22) -> 34.263683 | H22: No. | I22: Area Name | J22: Space (m2) | K22: Ref. distance (m) | P22: =Q22*(1+R22)*12+S22 -> 0 | V22: =U22*$P22 -> 0 | W22: =V22*$T22 -> 0 | X22: =W22*$T22 -> 0 | Y22: =X22*$T22 -> 0 | Z22: =Y22*$T22 -> 0
C23: 15 | D23: VOR Packing | E23: 300 | H23: 1 | I23: Non-critical DG | J23: 1000 | K23: =SQRT(J23) -> 31.622777
C24: 16 | D24: Stock Packing C303 | E24: 738
C25: 17 | D25: Stock Packing C302 | E25: 800
C26: 18 | D26: Packaging Storage | E26: 159
C27: 19 | D27: Floor Storage C301 | E27: 5872 | F27: =SQRT(E27) -> 76.628976 | P27: Inbound lines/year | R27: =Volume!B7+Volume!B11 -> 217050.18 | S27: incl. return
C28: 20 | D28: Canopy | E28: 2470 | P28: Inbound lines/day | R28: =R27/Parameter!P4 -> 740.78561
C29: 21 | D29: Other public Area | P29: Outbound lines/year | R29: =Volume!B56 -> 699921.88
P30: Outbound lines/day | R30: =R29/Parameter!P4 -> 2388.8119
H31: Exluding slow moving
C32: Total storage space - non DG | E32: =E18+E19+E21+E22+E27+J5 -> 21592 | F32: =E32/$E$2 -> 0.74643067 | H32: =E32-J5 -> 16392 | I32: % in C3 | O32: Process - Tier 1 | R32: Assumption/ Cal. | S32: UOM
D33: Racking | E33: =E18+E19 -> 8791 | F33: =E33/$E$32 -> 0.40714153 | H33: =E33 -> 8791 | I33: =H33/$H$32 -> 0.53629819 | O33: Inbound processing | P33: Unloading | R33: =(Volume!B7+Volume!B11)/Volume!H23 -> 154.15496 | S33: line per truck/cntr.
D34: Floor | E34: =E21+E27+J5 -> 11627 | F34: =E34/$E$32 -> 0.53848648 | H34: =E34-J5 -> 6427 | I34: =H34/$H$32 -> 0.3920815 | R34: =1.2*0.8*1.5 -> 1.44 | S34: CBM per HU
D35: Shelving | E35: =E22 -> 1174 | F35: =E35/$E$32 -> 0.05437199 | H35: =E35 -> 1174 | I35: =H35/$H$32 -> 0.071620303 | R35: =Volume!H14/Volume!H23/Parameter!R34 -> 28.536241 | S35: HU per truck/cntr. | T35: =R35*Volume!H23/P4 -> 137.12979 | U35: HU per day
C36: Total storage space - DG | E36: =J23 -> 1000 | F36: =E36/$E$2 -> 0.034569779 | R36: 1 | S36: HU per trip
C37: Total packing space | E37: =E23+E24+E25+E26 -> 1997 | F37: =E37/$E$2 -> 0.069035849 | P37: Customs inspection | R37: 1 | S37: lines per trip
C38: Total staging incl. canopy | E38: =E13+E14+E17+E28+E12+E20 -> 3731 | F38: =E38/$E$2 -> 0.12897985 | P38: Sorting ALL | R38: =第二轮数据!C3 -> 0.5 | S38: mixed HU | T38: =T35*R38 -> 68.564894 | U38: Mixed HU
C39: Labelling space | E39: =E11 -> 200 | F39: =E39/$E$2 -> 0.0069139558 | R39: =第二轮数据!C5 -> 15.19 | S39: Piece per line | T39: =T35-T38 -> 68.564894 | U39: Single HU
R40: =(R28-T39)/T38 -> 9.8041531 | S40: line per mixed HU
C41: Distance | P41: New parts handling | R41: =Volume!F47 -> 0 | S41: of total inbound | T41: full inspeciton | U41: 0.06 | V41: (3%~8%)
P42: Warranty and Return | R42: 2 | S42: Piece per line
...

Sheet Process
A1: No. | B1: Rate-operation | C1: Area-2 | D1: Main-Process | E1: Sub-Process | F1: Daily Volume (2026) | G1: UOM (HU) | H1: Index | I1: Distance (m) | J1: MHE | K1: MHE speed | L1: Time (sec.) - movement | M1: Time (sec.) /handling | N1: Total Time (sec.) | O1: Role | P1: FTE | Q1: Packing Station | R1: HPJ with Scale | S1: Customize 1 | T1: Customize 2 | U1: Customize 3 | V1: Customize 4 | W1: Customize 5 | X1: FTE-Y2 | Y1: FTE-Y3 | Z1: FTE-Y4 | AA1: FTE-Y5 | AB1: FTE Cost - Y1 | AC1: FTE Cost - Y2 | AD1: FTE Cost - Y3 | AE1: FTE Cost - Y4 | AF1: FTE Cost - Y5
A2: =ROW()-1 -> 1 | B2: Inbound processing | C2: Make IB plan | D2: Make IB plan and paper work | E2: Check IB Plan | F2: 1 | G2: Daily | H2: HDL | I2: =IFERROR(VLOOKUP(H2,Parameter!$F$44:$H$92,3,0),"") -> 0 | J2: Manual | K2: =IFERROR(INDEX(Parameter!$D$122:$M$122,1,MATCH(Process!$J2,Parameter!$D$121:$M$121,0)),"") -> 1.2 | L2: =IFERROR(I2/K2,0) -> 0 | M2: =2*3600 -> 7200 | N2: =L2+M2 -> 7200 | O2: IB Planner | P2: =N2*F2/3600/Parameter!$P$6/Parameter!$P$7 -> 0.29411765 | X2: =P2*Parameter!W$8 -> 0.28529412 | Y2: =X2*Parameter!X$8 -> 0.26306457 | Z2: =Y2*Parameter!Y$8 -> 0.24984412 | AA2: =Z2*Parameter!Z$8 -> 0.24440671 | AB2: =VLOOKUP(O2,Parameter!$O$11:$P$22,2,0)*Process!P2 -> 37078.999 | AC2: =VLOOKUP($O2,Parameter!$O$11:$P$22,2,0)*VLOOKUP($O2,Parameter!$O$11:$T$22,6,0)*X2 -> 38484.293 | AD2: =VLOOKUP($O2,Parameter!$O$11:$P$22,2,0)*VLOOKUP($O2,Parameter!$O$11:$T$22,6,0)^2*Y2 -> 37969.671 | AE2: =VLOOKUP($O2,Parameter!$O$11:$P$22,2,0)*VLOOKUP($O2,Parameter!$O$11:$T$22,6,0)^3*Z2 -> 38585.789 | AF2: =VLOOKUP($O2,Parameter!$O$11:$P$22,2,0)*VLOOKUP($O2,Parameter!$O$11:$T$22,6,0)^4*AA2 -> 40388.261
A3: =ROW()-1 -> 2 | B3: Inbound processing | C3: Good Receiving | D3: Checking truck / container before unloading | E3: Adjust Dock | F3: =Volume!H23/Parameter!P4 -> 4.8054608 | G3: Truck/Ctnr. | H3: HDL | I3: =IFERROR(VLOOKUP(H3,Parameter!$F$44:$H$92,3,0),"") -> 0 | J3: Manual | K3: =IFERROR(INDEX(Parameter!$D$122:$M$122,1,MATCH(Process!$J3,Parameter!$D$121:$M$121,0)),"") -> 1.2 | L3: =IFERROR(I3/K3,0) -> 0 | M3: 120 | N3: =L3+M3 -> 120 | O3: Operator | P3: =N3*F3/3600/Parameter!$P$6/Parameter!$P$7 -> 0.02355618 | X3: =P3*Parameter!W$8 -> 0.022849495 | Y3: =X3*Parameter!X$8 -> 0.021069108 | Z3: =Y3*Parameter!Y$8 -> 0.020010268 | AA3: =Z3*Parameter!Z$8 -> 0.019574781 | AB3: =VLOOKUP(O3,Parameter!$O$11:$P$22,2,0)*Process!P3 -> 1979.7964 | AC3: =VLOOKUP($O3,Parameter!$O$11:$P$22,2,0)*VLOOKUP($O3,Parameter!$O$11:$T$22,6,0)*X3 -> 2054.8307 | AD3: =VLOOKUP($O3,Parameter!$O$11:$P$22,2,0)*VLOOKUP($O3,Parameter!$O$11:$T$22,6,0)^2*Y3 -> 2027.353 | AE3: =VLOOKUP($O3,Parameter!$O$11:$P$22,2,0)*VLOOKUP($O3,Parameter!$O$11:$T$22,6,0)^3*Z3 -> 2060.2499 | AF3: =VLOOKUP($O3,Parameter!$O$11:$P$22,2,0)*VLOOKUP($O3,Parameter!$O$11:$T$22,6,0)^4*AA3 -> 2156.4912
A4: =ROW()-1 -> 3 | B4: Inbound processing | C4: Good Receiving | D4: Checking truck / container before unloading | E4: Safety Confirm | F4: =F3 -> 4.8054608 | G4: Truck/Ctnr. | H4: HDL | I4: =IFERROR(VLOOKUP(H4,Parameter!$F$44:$H$92,3,0),"") -> 0 | J4: Manual | K4: =IFERROR(INDEX(Parameter!$D$122:$M$122,1,MATCH(Process!$J4,Parameter!$D$121:$M$121,0)),"") -> 1.2 | L4: =IFERROR(I4/K4,0) -> 0 | M4: 90 | N4: =L4+M4 -> 90 | O4: Operator | P4: =N4*F4/3600/Parameter!$P$6/Parameter!$P$7 -> 0.017667135 | X4: =P4*Parameter!W$8 -> 0.017137121 | Y4: =X4*Parameter!X$8 -> 0.015801831 | Z4: =Y4*Parameter!Y$8 -> 0.015007701 | AA4: =Z4*Parameter!Z$8 -> 0.014681086 | AB4: =VLOOKUP(O4,Parameter!$O$11:$P$22,2,0)*Process!P4 -> 1484.8473 | AC4: =VLOOKUP($O4,Parameter!$O$11:$P$22,2,0)*VLOOKUP($O4,Parameter!$O$11:$T$22,6,0)*X4 -> 1541.123 | AD4: =VLOOKUP($O4,Parameter!$O$11:$P$22,2,0)*VLOOKUP($O4,Parameter!$O$11:$T$22,6,0)^2*Y4 -> 1520.5147 | AE4: =VLOOKUP($O4,Parameter!$O$11:$P$22,2,0)*VLOOKUP($O4,Parameter!$O$11:$T$22,6,0)^3*Z4 -> 1545.1875 | AF4: =VLOOKUP($O4,Parameter!$O$11:$P$22,2,0)*VLOOKUP($O4,Parameter!$O$11:$T$22,6,0)^4*AA4 -> 1617.3684
A5: =ROW()-1 -> 4 | B5: Inbound processing | C5: Good Receiving | D5: Checking truck / container before unloading | E5: Check IB DN | F5: =F4 -> 4.8054608 | G5: Truck/Ctnr. | H5: HDL | I5: =IFERROR(VLOOKUP(H5,Parameter!$F$44:$H$92,3,0),"") -> 0 | J5: Manual | K5: =IFERROR(INDEX(Parameter!$D$122:$M$122,1,MATCH(Process!$J5,Parameter!$D$121:$M$121,0)),"") -> 1.2 | L5: =IFERROR(I5/K5,0) -> 0 | M5: 15 | N5: =L5+M5 -> 15 | O5: Operator | P5: =N5*F5/3600/Parameter!$P$6/Parameter!$P$7 -> 0.0029445225 | X5: =P5*Parameter!W$8 -> 0.0028561868 | Y5: =X5*Parameter!X$8 -> 0.0026336385 | Z5: =Y5*Parameter!Y$8 -> 0.0025012836 | AA5: =Z5*Parameter!Z$8 -> 0.0024468476 | AB5: =VLOOKUP(O5,Parameter!$O$11:$P$22,2,0)*Process!P5 -> 247.47455 | AC5: =VLOOKUP($O5,Parameter!$O$11:$P$22,2,0)*VLOOKUP($O5,Parameter!$O$11:$T$22,6,0)*X5 -> 256.85384 | AD5: =VLOOKUP($O5,Parameter!$O$11:$P$22,2,0)*VLOOKUP($O5,Parameter!$O$11:$T$22,6,0)^2*Y5 -> 253.41912 | AE5: =VLOOKUP($O5,Parameter!$O$11:$P$22,2,0)*VLOOKUP($O5,Parameter!$O$11:$T$22,6,0)^3*Z5 -> 257.53124 | AF5: =VLOOKUP($O5,Parameter!$O$11:$P$22,2,0)*VLOOKUP($O5,Parameter!$O$11:$T$22,6,0)^4*AA5 -> 269.56139
A6: =ROW()-1 -> 5 | B6: Inbound processing | C6: Good Receiving | D6: Checking truck / container before unloading | E6: Check Container | F6: =F5 -> 4.8054608 | G6: Truck/Ctnr. | H6: HDL | I6: =IFERROR(VLOOKUP(H6,Parameter!$F$44:$H$92,3,0),"") -> 0 | J6: Manual | K6: =IFERROR(INDEX(Parameter!$D$122:$M$122,1,MATCH(Process!$J6,Parameter!$D$121:$M$121,0)),"") -> 1.2 | L6: =IFERROR(I6/K6,0) -> 0 | M6: 75 | N6: =L6+M6 -> 75 | O6: Operator | P6: =N6*F6/3600/Parameter!$P$6/Parameter!$P$7 -> 0.014722613 | X6: =P6*Parameter!W$8 -> 0.014280934 | Y6: =X6*Parameter!X$8 -> 0.013168192 | Z6: =Y6*Parameter!Y$8 -> 0.012506418 | AA6: =Z6*Parameter!Z$8 -> 0.012234238 | AB6: =VLOOKUP(O6,Parameter!$O$11:$P$22,2,0)*Process!P6 -> 1237.3727 | AC6: =VLOOKUP($O6,Parameter!$O$11:$P$22,2,0)*VLOOKUP($O6,Parameter!$O$11:$T$22,6,0)*X6 -> 1284.2692 | AD6: =VLOOKUP($O6,Parameter!$O$11:$P$22,2,0)*VLOOKUP($O6,Parameter!$O$11:$T$22,6,0)^2*Y6 -> 1267.0956 | AE6: =VLOOKUP($O6,Parameter!$O$11:$P$22,2,0)*VLOOKUP($O6,Parameter!$O$11:$T$22,6,0)^3*Z6 -> 1287.6562 | AF6: =VLOOKUP($O6,Parameter!$O$11:$P$22,2,0)*VLOOKUP($O6,Parameter!$O$11:$T$22,6,0)^4*AA6 -> 1347.807
A7: =ROW()-1 -> 6 | B7: Inbound processing | C7: Good Receiving | D7: Checking truck / container before unloading | E7: Open Container | F7: =F6 -> 4.8054608 | G7: Truck/Ctnr. | H7: HDL | I7: =IFERROR(VLOOKUP(H7,Parameter!$F$44:$H$92,3,0),"") -> 0 | J7: Manual | K7: =IFERROR(INDEX(Parameter!$D$122:$M$122,1,MATCH(Process!$J7,Parameter!$D$121:$M$121,0)),"") -> 1.2 | L7: =IFERROR(I7/K7,0) -> 0 | M7: 75 | N7: =L7+M7 -> 75 | O7: Operator | P7: =N7*F7/3600/Parameter!$P$6/Parameter!$P$7 -> 0.014722613 | X7: =P7*Parameter!W$8 -> 0.014280934 | Y7: =X7*Parameter!X$8 -> 0.013168192 | Z7: =Y7*Parameter!Y$8 -> 0.012506418 | AA7: =Z7*Parameter!Z$8 -> 0.012234238 | AB7: =VLOOKUP(O7,Parameter!$O$11:$P$22,2,0)*Process!P7 -> 1237.3727 | AC7: =VLOOKUP($O7,Parameter!$O$11:$P$22,2,0)*VLOOKUP($O7,Parameter!$O$11:$T$22,6,0)*X7 -> 1284.2692 | AD7: =VLOOKUP($O7,Parameter!$O$11:$P$22,2,0)*VLOOKUP($O7,Parameter!$O$11:$T$22,6,0)^2*Y7 -> 1267.0956 | AE7: =VLOOKUP($O7,Parameter!$O$11:$P$22,2,0)*VLOOKUP($O7,Parameter!$O$11:$T$22,6,0)^3*Z7 -> 1287.6562 | AF7: =VLOOKUP($O7,Parameter!$O$11:$P$22,2,0)*VLOOKUP($O7,Parameter!$O$11:$T$22,6,0)^4*AA7 -> 1347.807
A8: =ROW()-1 -> 7 | B8: Inbound processing | C8: Good Receiving | D8: Checking truck / container before unloading | E8: Adjust Dock | F8: =F7 -> 4.8054608 | G8: Truck/Ctnr. | H8: HDL | I8: =IFERROR(VLOOKUP(H8,Parameter!$F$44:$H$92,3,0),"") -> 0 | J8: Manual | K8: =IFERROR(INDEX(Parameter!$D$122:$M$122,1,MATCH(Process!$J8,Parameter!$D$121:$M$121,0)),"") -> 1.2 | L8: =IFERROR(I8/K8,0) -> 0 | M8: 45 | N8: =L8+M8 -> 45 | O8: Operator | P8: =N8*F8/3600/Parameter!$P$6/Parameter!$P$7 -> 0.0088335676 | X8: =P8*Parameter!W$8 -> 0.0085685605 | Y8: =X8*Parameter!X$8 -> 0.0079009154 | Z8: =Y8*Parameter!Y$8 -> 0.0075038507 | AA8: =Z8*Parameter!Z$8 -> 0.0073405428 | AB8: =VLOOKUP(O8,Parameter!$O$11:$P$22,2,0)*Process!P8 -> 742.42365 | AC8: =VLOOKUP($O8,Parameter!$O$11:$P$22,2,0)*VLOOKUP($O8,Parameter!$O$11:$T$22,6,0)*X8 -> 770.56151 | AD8: =VLOOKUP($O8,Parameter!$O$11:$P$22,2,0)*VLOOKUP($O8,Parameter!$O$11:$T$22,6,0)^2*Y8 -> 760.25736 | AE8: =VLOOKUP($O8,Parameter!$O$11:$P$22,2,0)*VLOOKUP($O8,Parameter!$O$11:$T$22,6,0)^3*Z8 -> 772.59373 | AF8: =VLOOKUP($O8,Parameter!$O$11:$P$22,2,0)*VLOOKUP($O8,Parameter!$O$11:$T$22,6,0)^4*AA8 -> 808.68418
A9: =ROW()-1 -> 8 | B9: Inbound processing | C9: Good Receiving | D9: Unloading the truck / container | E9: Unloading Cargos | F9: =F3*Parameter!R35 -> 137.12979 | G9: HU | H9: HDL | I9: =IFERROR(VLOOKUP(H9,Parameter!$F$44:$H$92,3,0),"") -> 0 | J9: CB | K9: =IFERROR(INDEX(Parameter!$D$122:$M$122,1,MATCH(Process!$J9,Parameter!$D$121:$M$121,0)),"") -> 2.7777778 | L9: =IFERROR(I9/K9,0) -> 0 | M9: 30 | N9: =L9+M9 -> 30 | O9: MHE Driver | P9: =N9*F9/3600/Parameter!$P$6/Parameter!$P$7 -> 0.16805121 | X9: =P9*Parameter!W$8 -> 0.16300967 | Y9: =X9*Parameter!X$8 -> 0.15030829 | Z9: =Y9*Parameter!Y$8 -> 0.14275446 | AA9: =Z9*Parameter!Z$8 -> 0.13964767 | AB9: =VLOOKUP(O9,Parameter!$O$11:$P$22,2,0)*Process!P9 -> 16948.784 | AC9: =VLOOKUP($O9,Parameter!$O$11:$P$22,2,0)*VLOOKUP($O9,Parameter!$O$11:$T$22,6,0)*X9 -> 17591.143 | AD9: =VLOOKUP($O9,Parameter!$O$11:$P$22,2,0)*VLOOKUP($O9,Parameter!$O$11:$T$22,6,0)^2*Y9 -> 17355.91 | AE9: =VLOOKUP($O9,Parameter!$O$11:$P$22,2,0)*VLOOKUP($O9,Parameter!$O$11:$T$22,6,0)^3*Z9 -> 17637.537 | AF9: =VLOOKUP($O9,Parameter!$O$11:$P$22,2,0)*VLOOKUP($O9,Parameter!$O$11:$T$22,6,0)^4*AA9 -> 18461.446
